Workbook

Sheet AU-Stock Supported
M1: Total | N1: =SUM(N3:N3) -> 2472
A2: Plant | B2: Branch # | C2: Date of PO | D2: PO Ref | E2: Simba Ref# | F2: Product Code | G2: Product | H2: Ordered Qty | I2: Invoiced Qty | J2: % Delivered | K2: Backorder Qty | L2: On Pick Qty | M2: Sell Price $ | N2: Backorder $ | O2: ETA (Mel Warehouse) | P2: Stock Type | Q2: Demand Exceeding Forecast | R2: Comments
A3: =VLOOKUP(B3,Plants!$A$2:$B$39,2,0) -> Murdoch Linen | B3: 77 | C3: 46056 | D3: 22900 | E3: SO00374090 | F3: 1728 | G3: HUCK TWL GREEN 60x90 | H3: 800 | I3: 0 | J3: 0 | K3: 800 | L3: 0 | M3: 3.09 | N3: 2472 | O3: TBC | P3: SS

Sheet AU-Made to Order
M1: Total | N1: =SUM(N3:N45) -> 267664.9
A2: Plant | B2: Branch # | C2: Date of PO | D2: PO Ref# | E2: Simba Ref# | F2: Product Code | G2: Product | H2: Ordered Qty | I2: Invoiced Qty | J2: % Delivered | K2: Backorder Qty | L2: On Pick Qty | M2: Sell Price $ | N2: Backorder $ | O2: ETA (Mel Warehouse) | P2: Stock Type (Prposed) | Q2: Comments
A3: =VLOOKUP(B3,Plants!$A$2:$B$39,2,0) -> Murdoch Linen | B3: 77 | C3: 46056 | D3: 22900 | E3: SO00374090 | F3: 5702 | G3: DRAPE GREEN 135X120 | H3: 500 | I3: 0 | J3: 0 | K3: 500 | L3: 0 | M3: 3.98 | N3: 1990 | O3: 46129 | P3: MTO
A4: =VLOOKUP(B4,Plants!$A$2:$B$39,2,0) -> Murdoch Linen | B4: 77 | C4: 46000 | D4: 22165 | E4: SO00371698 | F4: 13214 | G4: GOWN PC STUD SHLD/CHEST GREEN | H4: 990 | I4: 0 | J4: 0 | K4: 990 | L4: 0 | M4: 13.34 | N4: 13206.6 | O4: 46129 | P4: MTO
A5: =VLOOKUP(B5,Plants!$A$2:$B$39,2,0) -> Murdoch Linen | B5: 77 | C5: 46056 | D5: 22900 | E5: SO00374090 | F5: 13214 | G5: GOWN PC STUD SHLD/CHEST GREEN | H5: 510 | I5: 0 | J5: 0 | K5: 510 | L5: 0 | M5: 13.34 | N5: 6803.4 | O5: 46164 | P5: MTO
A6: =VLOOKUP(B6,Plants!$A$2:$B$39,2,0) -> Murdoch Linen | B6: 77 | C6: 46091 | D6: 23576 | E6: SO00375951 | F6: 13214 | G6: GOWN PC STUD SHLD/CHEST GREEN | H6: 300 | I6: 0 | J6: 0 | K6: 300 | L6: 0 | M6: 13.34 | N6: 4002 | O6: 46164 | P6: MTO
A7: =VLOOKUP(B7,Plants!$A$2:$B$39,2,0) -> Murdoch Linen | B7: 77 | C7: 46091 | D7: 23577 | E7: SO00375947 | F7: 13214 | G7: GOWN PC STUD SHLD/CHEST GREEN | H7: 600 | I7: 0 | J7: 0 | K7: 600 | L7: 0 | M7: 13.34 | N7: 8004 | O7: 46164 | P7: MTO
A8: =VLOOKUP(B8,Plants!$A$2:$B$39,2,0) -> Murdoch Linen | B8: 77 | C8: 46076 | D8: 23290 | E8: SO00375234 | F8: 15081 | G8: CLOTH PRIVACY CT WH 60X60 RFID | H8: 350 | I8: 0 | J8: 0 | K8: 350 | L8: 0 | M8: 3.54 | N8: 1239 | O8: 46164 | P8: MTO
A9: =VLOOKUP(B9,Plants!$A$2:$B$39,2,0) -> Murdoch Linen | B9: 77 | C9: 46056 | D9: 22900 | E9: SO00374090 | F9: 15083 | G9: SHEET PROC PC BLUE 50X140 RFID | H9: 500 | I9: 0 | J9: 0 | K9: 500 | L9: 0 | M9: 3.44 | N9: 1720 | O9: 46164 | P9: MTO
A10: =VLOOKUP(B10,Plants!$A$2:$B$39,2,0) -> Murdoch Linen | B10: 77 | C10: 46056 | D10: 22900 | E10: SO00374090 | F10: 15241 | G10: SHEET WHITE C28 PAT 1661 RFID INVENGO CHIP | H10: 350 | I10: 0 | J10: 0 | K10: 350 | L10: 0 | M10: 5.36 | N10: 1876 | O10: 46157 | P10: MTO
A11: =VLOOKUP(B11,Plants!$A$2:$B$39,2,0) -> Murdoch Linen | B11: 77 | C11: 46076 | D11: 23290 | E11: SO00375234 | F11: 15244 | G11: PANT PYJ SAND LGE/41 4180 RFID INVENGO CHIP | H11: 700 | I11: 630 | J11: 0.9 | K11: 70 | L11: 0 | M11: 4.62 | N11: 323.4 | O11: 46164 | P11: MTO
A12: =VLOOKUP(B12,Plants!$A$2:$B$39,2,0) -> Murdoch Linen | B12: 77 | C12: 46056 | D12: 22900 | E12: SO00374091 | F12: 15247 | G12: COAT PYJ GREEN XL/43 4576 RFID INVENGO CHIP | H12: 500 | I12: 0 | J12: 0 | K12: 500 | L12: 0 | M12: 4.13 | N12: 2065 | O12: 46164 | P12: MTO
A13: =VLOOKUP(B13,Plants!$A$2:$B$39,2,0) -> Murdoch Linen | B13: 77 | C13: 46076 | D13: 23290 | E13: SO00375234 | F13: 15247 | G13: COAT PYJ GREEN XL/43 4576 RFID INVENGO CHIP | H13: 500 | I13: 0 | J13: 0 | K13: 500 | L13: 0 | M13: 4.13 | N13: 2065 | O13: 46192 | P13: MTO
A14: =VLOOKUP(B14,Plants!$A$2:$B$39,2,0) -> Murdoch Linen | B14: 77 | C14: 46056 | D14: 22900 | E14: SO00374090 | F14: 15251 | G14: PYJAMA PANT SUMMER/6 5572 RFID INVENGO CHIP | H14: 280 | I14: 0 | J14: 0 | K14: 280 | L14: 0 | M14: 2.35 | N14: 658 | O14: 46164 | P14: MTO
... A45: =VLOOKUP(B45,Plants!$A$2:$B$39,2,0) -> Murdoch Linen | B45: 77 | C45: 46062 | D45: 23050 & 21937 | E45: SO00374474 | F45: 17496 | G45: BAG POLY LINEN BLUE ZIP 37X37X75 | H45: 350 | I45: 0 | J45: 0 | K45: 350 | L45: 0 | M45: 9.75 | N45: 3412.5 | O45: 46157 | P45: MTO

Sheet NZ- Stock Supported
A1: Back order Report - Stock Supported | K1: Total | L1: =SUM(L3:L44) -> 88227.16
A2: Customer Name | B2: Input Date | C2: Cust PO # | D2: Simba Ref# | E2: Product Code | F2: Display Name | G2: Ordered Qty | H2: Invoiced Qty | I2: % of Stock Delivered | J2: Backorder Qty | K2: Item Price | L2: $ | M2: Stock Group | O2: Estimated Delivery Date | P2: Comments
A3: NELSON | B3: 45254 | C3: 4318685 | D3: SO00339183 | E3: P0586765010 | F3: GOWN ALL PURPOSE GREEN M MO108 | G3: 40 | H3: 0 | I3: 0 | J3: 40 | K3: 10.33 | L3: 413.2 | M3: SS | N3: BSR | O3: 45366
A4: NELSON | B4: 45254 | C4: 4318687 | D4: SO00339185 | E4: P0586765010 | F4: GOWN ALL PURPOSE GREEN M MO108 | G4: 40 | H4: 0 | I4: 0 | J4: 40 | K4: 10.33 | L4: 413.2 | M4: SS | N4: BSR | O4: 45366
A5: NELSON | B5: 45295 | C5: 4319618 | D5: SO00340821 | E5: P0586765010 | F5: GOWN ALL PURPOSE GREEN M MO108 | G5: 40 | H5: 0 | I5: 0 | J5: 40 | K5: 10.33 | L5: 413.2 | M5: SS | N5: BSR | O5: 45366
A6: NELSON | B6: 45310 | C6: 4320024 | D6: SO00341448 | E6: P0586765010 | F6: GOWN ALL PURPOSE GREEN M MO108 | G6: 40 | H6: 0 | I6: 0 | J6: 40 | K6: 10.33 | L6: 413.2 | M6: SS | N6: BSR | O6: 45366
A7: NELSON | B7: 45310 | C7: 4320024 | D7: SO00341448 | E7: P9940007 | F7: TABLECLOTH DESIGNER PLAIN WHITE 137X137CM (40/CTN) | G7: 40 | H7: 0 | I7: 0 | J7: 40 | K7: 5.46 | L7: 218.4 | M7: SS | N7: BSR | O7: 45350
A8: NELSON | B8: 45310 | C8: 4320024 | D8: SO00341448 | E8: P9940009 | F8: TABLECLOTH DESIGNER PLAIN WHITE 137X244CM (20/CTN) | G8: 40 | H8: 0 | I8: 0 | J8: 40 | K8: 9.12 | L8: 364.8 | M8: SS | N8: BSR | O8: 45350
A9: PT CHEV | B9: 45245 | C9: 4318395 | D9: SO00338719 | E9: P0586765010 | F9: GOWN ALL PURPOSE GREEN M MO108 | G9: 640 | H9: 102 | I9: 0.159375 | J9: 538 | K9: 10.33 | L9: 5557.54 | M9: SS | N9: BSR | O9: 45343
A10: PT CHEV | B10: 45254 | C10: 4318681 | D10: SO00339184 | E10: P0586832767 | F10: DRESS GUARD PASTEL GREEN 44X55CM (NO LABELS) | G10: 2000 | H10: 60 | I10: 0.03 | J10: 1940 | K10: 2.08 | L10: 4035.2 | M10: SS | N10: BSR | O10: 45343
A11: PT CHEV | B11: 45266 | C11: 4319038 | D11: SO00339741 | E11: P0586765010 | F11: GOWN ALL PURPOSE GREEN M MO108 | G11: 500 | H11: 0 | I11: 0 | J11: 500 | K11: 10.33 | L11: 5165 | M11: SS | N11: BSR | O11: 45343
A12: PT CHEV | B12: 45278 | C12: 4319314 | D12: SO00340372 | E12: P0586765010 | F12: GOWN ALL PURPOSE GREEN M MO108 | G12: 500 | H12: 0 | I12: 0 | J12: 500 | K12: 10.33 | L12: 5165 | M12: SS | N12: BSR | O12: 45343
A13: PT CHEV | B13: 45278 | C13: 4319314 | D13: SO00340372 | E13: P0586773039 | F13: THEATRE TOWEL PASTEL GREEN 72X90CM (NO LABELS) | G13: 250 | H13: 200 | I13: 0.8 | J13: 50 | K13: 2.13 | L13: 106.5 | M13: SS | N13: BSR | O13: 45343
A14: PT CHEV | B14: 45313 | C14: 4320080 | D14: SO00341503 | E14: P0586867820-TGP | F14: SHEET FLAT HOSPITAL GREEN PRINT LONG SINGLE 177X305CM - TGP | G14: 4520 | H14: 1720 | I14: 0.38053097 | J14: 2800 | K14: 7.3 | L14: 20440 | M14: SS | N14: BSR | O14: 45362
A15: PT CHEV | B15: 45217 | C15: 4319698 | D15: SO00337498 | E15: P99400617 | F15: SHEET FLAT TAYLORS WHITE SUPER KING 70/30 320X300CM 12PK | G15: 2712 | H15: 2078 | I15: 0.76622419 | J15: 634 | K15: 17.88 | L15: 11335.92 | M15: SS | N15: BSR | O15: 45397
A16: PT CHEV | B16: 45254 | C16: 4318681 | D16: SO00339184 | E16: P0586793211 | F16: DRAW SHEET PASTEL GREEN 85X186CM (NO LABELS) | G16: 3000 | H16: 1040 | I16: 0.34666667 | J16: 1960 | K16: 4.32 | L16: 8467.2 | M16: SS | N16: BSR | O16: 45350
A17: PT CHEV | B17: 45267 | C17: 4319077 | D17: SO00339828 | E17: P99400617 | F17: SHEET FLAT TAYLORS WHITE SUPER KING 70/30 320X300CM 12PK | G17: 600 | H17: 0 | I17: 0 | J17: 600 | K17: 17.88 | L17: 10728 | M17: SS | N17: BSR | O17: 45397
A18: PT CHEV | B18: 45278 | C18: 4319314 | D18: SO00340372 | E18: P0586772513 | F18: BABY NIGHTDRESS FLANNELETTE WHITE | G18: 300 | H18: 180 | I18: 0.6 | J18: 120 | K18: 1.9 | L18: 228 | M18: SS | N18: BSR | O18: 45397
A19: PT CHEV | B19: 45280 | C19: 4319460 | D19: SO00340545 | E19: P0586765027 | F19: GOWN ALL PURPOSE GREEN XL MO108 | G19: 1000 | H19: 960 | I19: 0.96 | J19: 40 | K19: 10.4 | L19: 416 | M19: SS | N19: BSR | O19: 45397
A20: PT CHEV | B20: 45313 | C20: 4320080 | D20: SO00341503 | E20: P0586765010 | F20: GOWN ALL PURPOSE GREEN M MO108 | G20: 520 | H20: 0 | I20: 0 | J20: 520 | K20: 10.33 | L20: 5371.6 | M20: SS | N20: BSR | O20: 45350
A21: PT CHEV | B21: 45313 | C21: 4320080 | D21: SO00341503 | E21: P0586765027 | F21: GOWN ALL PURPOSE GREEN XL MO108 | G21: 800 | H21: 0 | I21: 0 | J21: 800 | K21: 10.4 | L21: 8320 | M21: SS | N21: BSR | O21: 45397
A22: PT CHEV | B22: 45313 | C22: 4320080 | D22: SO00341503 | E22: P9940007 | F22: TABLECLOTH DESIGNER PLAIN WHITE 137X137CM (40/CTN) | G22: 120 | H22: 0 | I22: 0 | J22: 120 | K22: 5.46 | L22: 655.2 | M22: SS | N22: BSR | O22: 45350

Sheet NZ- MTO
A1: Back order Report - MTO | K1: Total | L1: =SUM(L3:L136) -> 69813.24
A2: Customer Name | B2: Input Date | C2: Cust PO # | D2: Simba Ref# | E2: Product Code | F2: Display Name | G2: Ordered Qty | H2: Invoiced Qty | I2: % of Stock Delivered | J2: Backorder Qty | K2: Item Price | L2: $ | M2: Stock Group | O2: Estimated Delivery Date | P2: Comments
A3: NELSON | B3: 45313 | C3: 4320033 | D3: SO00341516 | E3: P0014326237 | F3: KINGDOM SHEET - 50/50 KING SINGLE FITTED WHITE 110X203+35CM 127GSM | G3: 600 | H3: 0 | I3: 0.07 | J3: 582 | K3: 14.3 | L3: 8580 | N3: OMNI | O3: 45373
A4: NELSON | B4: 45295 | C4: 4319618 | D4: SO00340821 | E4: P99209401 | F4: MOMIE NAPKIN WHITE 53X51CM (250/CTN) | G4: 250 | H4: 0 | I4: 0 | J4: 250 | K4: 0.82 | L4: 205 | N4: OMNI | O4: 45394
A5: NELSON | B5: 45254 | C5: 4318685 | D5: SO00339183 | E5: P0586765911-TGP | F5: CLOTHING PROTECTOR TIE BLUE 50X80CM - TGP | G5: 144 | H5: 0 | I5: 0 | J5: 144 | K5: 2.8 | L5: 403.2 | M5: MTO | N5: BSR | O5: 45408
A6: PT CHEV | B6: 45254 | C6: 4318681 | D6: SO00339184 | E6: P0586852741 | F6: SPINAL SHEET DOUBLE THICKNESS PASTEL GREEN | G6: 301 | H6: 49 | I6: 0.1627907 | J6: 252 | K6: 11.08 | L6: 2792.16 | N6: BSR | O6: New Demand plan to be provided from Taylors
A7: PT CHEV | B7: 45266 | C7: 4319038 | D7: SO00339741 | E7: P0586814190 | F7: PYJAMA COAT KIDS CHINA BLUE SIZE 6 (YELLOW) | G7: 30 | H7: 0 | I7: 0 | J7: 30 | K7: 7.39 | L7: 221.7 | N7: CMT | O7: TBC
A8: PT CHEV | B8: 45266 | C8: 4319038 | D8: SO00339741 | E8: P0586814206 | F8: PYJAMA COAT KIDS CHINA BLUE SIZE 8 (BROWN) | G8: 30 | H8: 4 | I8: 0.13333333 | J8: 26 | K8: 13.49 | L8: 350.74 | M8: MTO | N8: CMT | O8: TBC
A9: PT CHEV | B9: 45266 | C9: 4319038 | D9: SO00339741 | E9: P0586814213 | F9: PYJAMA PANT KIDS CHINA BLUE SIZE 6 (YELLOW) | G9: 30 | H9: 0 | I9: 0 | J9: 30 | K9: 6.72 | L9: 201.6 | N9: CMT | O9: TBC
A10: PT CHEV | B10: 45266 | C10: 4319038 | D10: SO00339741 | E10: P0586814220 | F10: PYJAMA PANT KIDS CHINA BLUE SIZE 8 (BROWN) | G10: 30 | H10: 4 | I10: 0.13333333 | J10: 26 | K10: 12.27 | L10: 319.02 | N10: CMT | O10: TBC
A11: PT CHEV | B11: 45278 | C11: 4319314 | D11: SO00340372 | E11: P0586789993 | F11: PYJAMA COAT KIDS CHINA BLUE SIZE 4 (GREEN) | G11: 30 | H11: 2 | I11: 0.066666667 | J11: 28 | K11: 13.49 | L11: 377.72 | N11: CMT | O11: TBC
A12: PT CHEV | B12: 45278 | C12: 4319314 | D12: SO00340372 | E12: P0586814190 | F12: PYJAMA COAT KIDS CHINA BLUE SIZE 6 (YELLOW) | G12: 30 | H12: 0 | I12: 0 | J12: 30 | K12: 7.39 | L12: 221.7 | N12: CMT | O12: TBC
A13: PT CHEV | B13: 45278 | C13: 4319314 | D13: SO00340372 | E13: P0586814206 | F13: PYJAMA COAT KIDS CHINA BLUE SIZE 8 (BROWN) | G13: 30 | H13: 0 | I13: 0 | J13: 30 | K13: 13.49 | L13: 404.7 | M13: MTO | N13: CMT | O13: TBC
A14: PT CHEV | B14: 45278 | C14: 4319314 | D14: SO00340372 | E14: P0586814213 | F14: PYJAMA PANT KIDS CHINA BLUE SIZE 6 (YELLOW) | G14: 30 | H14: 0 | I14: 0 | J14: 30 | K14: 6.72 | L14: 201.6 | N14: CMT | O14: TBC
A15: PT CHEV | B15: 45278 | C15: 4319314 | D15: SO00340372 | E15: P0586814220 | F15: PYJAMA PANT KIDS CHINA BLUE SIZE 8 (BROWN) | G15: 30 | H15: 0 | I15: 0 | J15: 30 | K15: 12.27 | L15: 368.1 | N15: CMT | O15: TBC
A16: PT CHEV | B16: 45308 | C16: 4319948 | D16: SO00341320 | E16: P99802 | F16: BT COVER | G16: 300 | H16: 0 | I16: 0 | J16: 300 | K16: 52.58 | L16: 15774 | N16: BSR | O16: Made to Order - 16/02
A17: PT CHEV | B17: 45308 | C17: 4319948 | D17: SO00341320 | E17: P99819 | F17: SIDE SHEETS | G17: 100 | H17: 0 | I17: 0 | J17: 100 | K17: 60.65 | L17: 6065 | N17: CMT | O17: Made to Order - 16/02
A18: PT CHEV | B18: 45308 | C18: 4319948 | D18: SO00341320 | E18: P99838 | F18: SPLIT SHEET | G18: 20 | H18: 0 | I18: 0 | J18: 20 | K18: 94.56 | L18: 1891.2 | N18: CMT | O18: Made to Order - 16/02
A19: PT CHEV | B19: 45308 | C19: 4319948 | D19: SO00341320 | E19: P99847 | F19: LITHO LEGGING | G19: 100 | H19: 99 | I19: 0.99 | J19: 1 | K19: 28.47 | L19: 28.47 | N19: CMT | O19: Made to Order - 16/02
A20: PT CHEV | B20: 45313 | C20: 4320080 | D20: SO00341503 | E20: P0586789993 | F20: PYJAMA COAT KIDS CHINA BLUE SIZE 4 (GREEN) | G20: 60 | H20: 0 | I20: 0 | J20: 60 | K20: 13.49 | L20: 809.4 | N20: CMT | O20: TBC
A21: PT CHEV | B21: 45313 | C21: 4320080 | D21: SO00341503 | E21: P0586814190 | F21: PYJAMA COAT KIDS CHINA BLUE SIZE 6 (YELLOW) | G21: 60 | H21: 0 | I21: 0 | J21: 60 | K21: 7.39 | L21: 443.4 | N21: CMT | O21: TBC
A22: PT CHEV | B22: 45313 | C22: 4320080 | D22: SO00341503 | E22: P0586814206 | F22: PYJAMA COAT KIDS CHINA BLUE SIZE 8 (BROWN) | G22: 60 | H22: 0 | I22: 0 | J22: 60 | K22: 13.49 | L22: 809.4 | M22: MTO | N22: CMT | O22: TBC
A23: PT CHEV | B23: 45313 | C23: 4320080 | D23: SO00341503 | E23: P0586814213 | F23: PYJAMA PANT KIDS CHINA BLUE SIZE 6 (YELLOW) | G23: 60 | H23: 0 | I23: 0 | J23: 60 | K23: 6.72 | L23: 403.2 | N23: CMT | O23: TBC
A24: PT CHEV | B24: 45313 | C24: 4320080 | D24: SO00341503 | E24: P0586814220 | F24: PYJAMA PANT KIDS CHINA BLUE SIZE 8 (BROWN) | G24: 60 | H24: 0 | I24: 0 | J24: 60 | K24: 12.27 | L24: 736.2 | N24: CMT | O24: TBC
A25: PT CHEV | B25: 45218 | C25: 4317600 | D25: SO00337536 | E25: CHI-STEM-FI8NZ | F25: IHG 80/20 PLAIN PILLOWCASE STD - EMB FIRM | G25: 720 | H25: 550 | I25: 0.76388889 | J25: 170 | K25: 4.62 | L25: 785.4 | N25: INDENT | O25: 45343
A26: PT CHEV | B26: 45267 | C26: 4319077 | D26: SO00339828 | E26: CHI-STEM-FI8NZ | F26: IHG 80/20 PLAIN PILLOWCASE STD - EMB FIRM | G26: 360 | H26: 0 | I26: 0 | J26: 360 | K26: 4.62 | L26: 1663.2 | N26: INDENT | O26: 45343
A27: PT CHEV | B27: 45217 | C27: 4319698 | D27: SO00337498 | E27: P0014299265 | F27: REGAL SHEET - 80/20 PILLOWCASE LODGE 55X92+20CM 127GSM | G27: 1500 | H27: 750 | I27: 0.5 | J27: 750 | K27: 3.25 | L27: 2437.5 | N27: OMNI | O27: 45349
A28: PT CHEV | B28: 45224 | C28: 4316893 | D28: SO00337753 | E28: 1CW4XL-4XL | F28: WHITE COVERALLS - 4XL - ELASTIC ON WRIST & ANKLE NO HOOD | G28: 50 | H28: 9 | I28: 0.18 | J28: 41 | K28: 25.57 | L28: 1048.37 | M28: MTO | N28: BSR | O28: 45374
A29: PT CHEV | B29: 45224 | C29: 4316893 | D29: SO00337753 | E29: 1CW5XL-5XL | F29: WHITE COVERALLS - 5XL - ELASTIC ON WRIST & ANKLE NO HOOD | G29: 14 | H29: 7 | I29: 0.5 | J29: 7 | K29: 25.57 | L29: 178.99 | M29: MTO | N29: BSR | O29: 45374
A30: PT CHEV | B30: 45224 | C30: 4316893 | D30: SO00337753 | E30: 1CW6XL-6XL | F30: WHITE COVERALLS - 6XL - ELASTIC ON WRIST & ANKLE NO HOOD | G30: 20 | H30: 15 | I30: 0.75 | J30: 5 | K30: 35.86 | L30: 179.3 | M30: MTO | N30: BSR | O30: 45374
A31: PT CHEV | B31: 45314 | C31: 4320121 | D31: SO00341602 | E31: 1CW3XL-3XL | F31: WHITE COVERALLS - 3XL - ELASTIC ON WRIST & ANKLE NO HOOD | G31: 20 | H31: 0 | I31: 0 | J31: 20 | K31: 31.33 | L31: 626.6 | M31: MTO | N31: BSR | O31: 45374
A32: PT CHEV | B32: 45314 | C32: 4320121 | D32: SO00341602 | E32: 1CW5XL-5XL | F32: WHITE COVERALLS - 5XL - ELASTIC ON WRIST & ANKLE NO HOOD | G32: 20 | H32: 0 | I32: 0 | J32: 20 | K32: 27.23 | L32: 544.6 | M32: MTO | N32: BSR | O32: 45374
A33: PT CHEV | B33: 45314 | C33: 4320121 | D33: SO00341602 | E33: 1CWL-LARGE | F33: WHITE COVERALLS - LARGE - ELASTIC ON WRIST & ANKLE NO HOOD | G33: 20 | H33: 0 | I33: 0 | J33: 20 | K33: 29.42 | L33: 588.4 | M33: MTO | N33: BSR | O33: 45374
A34: PT CHEV | B34: 45314 | C34: 4320121 | D34: SO00341602 | E34: 1CWM-MEDIUM | F34: WHITE COVERALLS - MEDIUM - ELASTIC ON WRIST & ANKLE NO HOOD | G34: 20 | H34: 0 | I34: 0 | J34: 20 | K34: 38.19 | L34: 763.8 | M34: MTO | N34: BSR | O34: 45374
A35: PT CHEV | B35: 45314 | C35: 4320121 | D35: SO00341602 | E35: 1CWS-SMALL | F35: WHITE COVERALLS - SMALL - ELASTIC ON WRIST & ANKLE NO HOOD | G35: 20 | H35: 0 | I35: 0 | J35: 20 | K35: 29.42 | L35: 588.4 | M35: MTO | N35: BSR | O35: 45374
A36: PT CHEV | B36: 45314 | C36: 4320121 | D36: SO00341602 | E36: 1CWXL-XL | F36: WHITE COVERALLS - XL - ELASTIC ON WRIST & ANKLE NO HOOD | G36: 20 | H36: 2 | I36: 0.1 | J36: 18 | K36: 31.33 | L36: 563.94 | M36: MTO | N36: BSR | O36: 45374
A37: PT CHEV | B37: 45152 | C37: 4315892 | D37: SO00334558 | E37: P0586765028 | F37: GOWN ALL PURPOSE GREEN/GREY 3XL (PURPLE) | G37: 60 | H37: 0 | I37: 0 | J37: 60 | K37: 41.01 | L37: 2460.6 | N37: CMT | O37: 45408
A38: PT CHEV | B38: 45173 | C38: 4316507 | D38: SO00335439 | E38: P0586765028 | F38: GOWN ALL PURPOSE GREEN/GREY 3XL (PURPLE) | G38: 100 | H38: 0 | I38: 0 | J38: 100 | K38: 41.01 | L38: 4101 | N38: CMT | O38: 45408
A39: PT CHEV | B39: 45173 | C39: 4316507 | D39: SO00335439 | E39: P0586765029 | F39: GOWN ALL PURPOSE GREEN/GREY 6XL (PINK) | G39: 100 | H39: 0 | I39: 0 | J39: 100 | K39: 41.58 | L39: 4158 | M39: MTO | N39: CMT | O39: 45408
A40: PT CHEV | B40: 45218 | C40: 4317600 | D40: SO00337536 | E40: CHI-STEM-SO8NZ | F40: IHG 80/20 PLAIN PILLOWCASE STD - EMB SOFT | G40: 720 | H40: 600 | I40: 0.83333333 | J40: 120 | K40: 4.62 | L40: 554.4 | N40: INDENT | O40: 45343
...

Sheet Plants
A1: Code | B1: Branch
A2: 11 | B2: Northcote
A3: 12 | B3: Northcote
A4: 13 | B4: Northcote
A5: 14 | B5: Northcote
A6: 15 | B6: Northcote
A7: 16 | B7: Northcote
A8: 17 | B8: Northcote
A9: 18 | B9: Northcote
A10: 19 | B10: Northcote
A11: 21 | B11: Punchbowl
A12: 22 | B12: North Rocks
A13: 24 | B13: Somersby
... A39: 79 | B39: Belmont WA
